<?xml version="1.0" ?>
<robot name="wheeltec_robot">

    <link name="base_link">
        <visual>
            <origin xyz=" 0 0 0.05" rpy="0 0 0" />
            <geometry>
                <box size="0.27 0.16 0.07"/>
            </geometry>
            <material name="white">
                <color rgba="1 1 1 1"/>
            </material>
        </visual>
    </link>   

    <joint name="left_wheel_joint" type="continuous">
        <origin xyz="-0.09 0.095 0.04" rpy="1.57 0 0"/>
        <parent link="base_link"/>
        <child link="left_wheel_link"/>
        <axis xyz="0 1 0"/>
    </joint>

    <link name="left_wheel_link">
        <visual>
            <origin xyz="0 0 0" rpy="0 0 0" />
            <geometry>
                <cylinder radius="0.04" length = "0.04"/>
            </geometry>
            <material name="black">
                <color rgba="0 0 0 1"/>
            </material>
        </visual>
    </link>

    <joint name="right_wheel_joint" type="continuous">
        <origin xyz="-0.09 -0.095 0.04" rpy="1.57 0 0"/>
        <parent link="base_link"/>
        <child link="right_wheel_link"/>
        <axis xyz="0 1 0"/>
    </joint>

    <link name="right_wheel_link">
        <visual>
            <origin xyz="0 0 0" rpy="0 0 0" />
            <geometry>
                <cylinder radius="0.04" length = "0.04"/>
            </geometry>
            <material name="black">
                <color rgba="0 0 0 1"/>
            </material>
        </visual>
    </link>

      <joint name="left_front_joint" type="continuous">
        <origin xyz="0.09 0.095 0.04" rpy="1.57 0 0"/>
        <parent link="base_link"/>
        <child link="left_front_link"/>
        <axis xyz="0 1 0"/>
    </joint>

    <link name="left_front_link">
        <visual>
            <origin xyz="0 0 0" rpy="0 0 0" />
            <geometry>
                <cylinder radius="0.04" length = "0.04"/>
            </geometry>
            <material name="black">
                <color rgba="0 0 0 1"/>
            </material>
        </visual>
    </link>

    <joint name="right_front_joint" type="continuous">
        <origin xyz="0.09 -0.095 0.04" rpy="1.57 0 0"/>
        <parent link="base_link"/>
        <child link="right_front_link"/>
        <axis xyz="0 1 0"/>
    </joint>

    <link name="right_front_link">
        <visual>
            <origin xyz="0 0 0" rpy="0 0 0" />
            <geometry>
                <cylinder radius="0.04" length = "0.04"/>
            </geometry>
            <material name="black">
                <color rgba="0 0 0 1"/>
            </material>
        </visual>
    </link>

    <joint name="laser_joint" type="fixed">
        <origin xyz="0.0316 0.0001 0.0950" rpy="0 0 3.14159"/>
        <parent link="base_link"/>
        <child link="laser_link"/>
    </joint>

    <link name="laser_link">
        <visual>
            <origin xyz="0 0 0" rpy="0 0 0" />
            <geometry>
                <cylinder radius="0.03" length="0.02"/>
            </geometry>
            <material name="dark_grey">
                <color rgba="0.3 0.3 0.3 1"/>
            </material>
        </visual>
    </link>


</robot>
